<?xml version="1.0"?>
<robot name="irb4400" xmlns:xacro="http://ros.org/wiki/xacro">

  <!-- Material -->
  <material name="gray">
    <color rgba="0.6 0.6 0.6 1.0"/>
  </material>

  <!-- Link0 (base) -->
  <link name="link0">
    <visual>
      <geometry>
        <mesh filename="package://irb4400_description/meshes/link0.stl" scale="0.001 0.001 0.001"/>
      </geometry>
      <material name="gray"/>
    </visual>
  </link>

  <!-- Joint1: link0 -> link1 -->
  <joint name="joint1" type="revolute">
    <parent link="link0"/>
    <child link="link1"/>
    <origin xyz="0 0 0.1" rpy="0 0 0"/>
    <axis xyz="0 0 1"/>
    <limit lower="-3.14" upper="3.14" effort="100" velocity="1.0"/>
  </joint>

  <!-- Link1 -->
  <link name="link1">
    <visual>
      <geometry>
        <mesh filename="package://irb4400_description/meshes/link1.stl" scale="0.001 0.001 0.001"/>
      </geometry>
      <material name="gray"/>
    </visual>
  </link>

  <!-- Joint2: link1 -> link2 -->
  <joint name="joint2" type="revolute">
    <parent link="link1"/>
    <child link="link2"/>
    <origin xyz="0 0 0.2" rpy="0 0 0"/>
    <axis xyz="0 1 0"/>
    <limit lower="-3.14" upper="3.14" effort="100" velocity="1.0"/>
  </joint>

  <!-- Link2 -->
  <link name="link2">
    <visual>
      <geometry>
        <mesh filename="package://irb4400_description/meshes/link2.stl" scale="0.001 0.001 0.001"/>
      </geometry>
      <material name="gray"/>
    </visual>
  </link>

  <!-- Joint3: link2 -> link3 -->
  <joint name="joint3" type="revolute">
    <parent link="link2"/>
    <child link="link3"/>
    <origin xyz="0 0 0.3" rpy="0 0 0"/>
    <axis xyz="0 1 0"/>
    <limit lower="-3.14" upper="3.14" effort="100" velocity="1.0"/>
  </joint>

  <!-- Link3 -->
  <link name="link3">
    <visual>
      <geometry>
        <mesh filename="package://irb4400_description/meshes/link3.stl" scale="0.001 0.001 0.001"/>
      </geometry>
      <material name="gray"/>
    </visual>
  </link>

  <!-- Joint4: link3 -> link4 -->
  <joint name="joint4" type="revolute">
    <parent link="link3"/>
    <child link="link4"/>
    <origin xyz="0 0 0.2" rpy="0 0 0"/>
    <axis xyz="1 0 0"/>
    <limit lower="-3.14" upper="3.14" effort="100" velocity="1.0"/>
  </joint>

  <!-- Link4 -->
  <link name="link4">
    <visual>
      <geometry>
        <mesh filename="package://irb4400_description/meshes/link4.stl" scale="0.001 0.001 0.001"/>
      </geometry>
      <material name="gray"/>
    </visual>
  </link>

  <!-- Joint5: link4 -> link5 -->
  <joint name="joint5" type="revolute">
    <parent link="link4"/>
    <child link="link5"/>
    <origin xyz="0 0 0.1" rpy="0 0 0"/>
    <axis xyz="0 1 0"/>
    <limit lower="-3.14" upper="3.14" effort="100" velocity="1.0"/>
  </joint>

  <!-- Link5 -->
  <link name="link5">
    <visual>
      <geometry>
        <mesh filename="package://irb4400_description/meshes/link5.stl" scale="0.001 0.001 0.001"/>
      </geometry>
      <material name="gray"/>
    </visual>
  </link>

  <!-- Joint6: link5 -> link6 -->
  <joint name="joint6" type="revolute">
    <parent link="link5"/>
    <child link="link6"/>
    <origin xyz="0 0 0.1" rpy="0 0 0"/>
    <axis xyz="1 0 0"/>
    <limit lower="-3.14" upper="3.14" effort="100" velocity="1.0"/>
  </joint>

  <!-- Link6 -->
  <link name="link6">
    <visual>
      <geometry>
        <mesh filename="package://irb4400_description/meshes/link6.stl" scale="0.001 0.001 0.001"/>
      </geometry>
      <material name="gray"/>
    </visual>
  </link>

  <!-- Transmissions pour ROS 2 Control -->
  <transmission name="joint1_trans">
    <type>transmission_interface/SimpleTransmission</type>
    <joint name="joint1">
      <hardwareInterface>hardware_interface/PositionJointInterface</hardwareInterface>
    </joint>
    <actuator name="joint1_motor">
      <mechanicalReduction>1</mechanicalReduction>
    </actuator>
  </transmission>

  <transmission name="joint2_trans">
    <type>transmission_interface/SimpleTransmission</type>
    <joint name="joint2">
      <hardwareInterface>hardware_interface/PositionJointInterface</hardwareInterface>
    </joint>
    <actuator name="joint2_motor">
      <mechanicalReduction>1</mechanicalReduction>
    </actuator>
  </transmission>

  <transmission name="joint3_trans">
    <type>transmission_interface/SimpleTransmission</type>
    <joint name="joint3">
      <hardwareInterface>hardware_interface/PositionJointInterface</hardwareInterface>
    </joint>
    <actuator name="joint3_motor">
      <mechanicalReduction>1</mechanicalReduction>
    </actuator>
  </transmission>

  <transmission name="joint4_trans">
    <type>transmission_interface/SimpleTransmission</type>
    <joint name="joint4">
      <hardwareInterface>hardware_interface/PositionJointInterface</hardwareInterface>
    </joint>
    <actuator name="joint4_motor">
      <mechanicalReduction>1</mechanicalReduction>
    </actuator>
  </transmission>

  <transmission name="joint5_trans">
    <type>transmission_interface/SimpleTransmission</type>
    <joint name="joint5">
      <hardwareInterface>hardware_interface/PositionJointInterface</hardwareInterface>
    </joint>
    <actuator name="joint5_motor">
      <mechanicalReduction>1</mechanicalReduction>
    </actuator>
  </transmission>

  <transmission name="joint6_trans">
    <type>transmission_interface/SimpleTransmission</type>
    <joint name="joint6">
      <hardwareInterface>hardware_interface/PositionJointInterface</hardwareInterface>
    </joint>
    <actuator name="joint6_motor">
      <mechanicalReduction>1</mechanicalReduction>
    </actuator>
  </transmission>
  
  <!-- Ros2_control -->
  <ros2_control name="IRB4400System" type="system">
    <hardware>
      <plugin>fake_components/GenericSystem</plugin>
    </hardware>

    <joint name="joint1">
      <interface>position</interface>
    </joint>
    <joint name="joint2">
      <interface>position</interface>
    </joint>
    <joint name="joint3">
      <interface>position</interface>
    </joint>
    <joint name="joint4">
      <interface>position</interface>
    </joint>
    <joint name="joint5">
      <interface>position</interface>
    </joint>
    <joint name="joint6">
      <interface>position</interface>
    </joint>
  </ros2_control>
  
</robot>
